2014-10-26 19:36:03,739 monitor.py[line:11] DEBUG test
2014-10-26 19:42:51,147 crawl.py[line:32] ERROR generic exception: Traceback (most recent call last):
  File "./crawl.py", line 19, in url_read
    content=urllib2.urlopen(req,timeout=60).read()
  File "/home/zhouqiang/.jumbo/lib/python2.7/socket.py", line 351, in read
    data = self._sock.recv(rbufsize)
  File "/home/zhouqiang/.jumbo/lib/python2.7/httplib.py", line 541, in read
    return self._read_chunked(amt)
  File "/home/zhouqiang/.jumbo/lib/python2.7/httplib.py", line 601, in _read_chunked
    value.append(self._safe_read(chunk_left))
  File "/home/zhouqiang/.jumbo/lib/python2.7/httplib.py", line 647, in _safe_read
    chunk = self.fp.read(min(amt, MAXAMOUNT))
  File "/home/zhouqiang/.jumbo/lib/python2.7/socket.py", line 380, in read
    data = self._sock.recv(left)
timeout: timed out

2014-10-26 19:42:51,148 crawl.py[line:32] ERROR generic exception: Traceback (most recent call last):
  File "./crawl.py", line 19, in url_read
    content=urllib2.urlopen(req,timeout=60).read()
  File "/home/zhouqiang/.jumbo/lib/python2.7/socket.py", line 351, in read
    data = self._sock.recv(rbufsize)
  File "/home/zhouqiang/.jumbo/lib/python2.7/httplib.py", line 541, in read
    return self._read_chunked(amt)
  File "/home/zhouqiang/.jumbo/lib/python2.7/httplib.py", line 601, in _read_chunked
    value.append(self._safe_read(chunk_left))
  File "/home/zhouqiang/.jumbo/lib/python2.7/httplib.py", line 647, in _safe_read
    chunk = self.fp.read(min(amt, MAXAMOUNT))
  File "/home/zhouqiang/.jumbo/lib/python2.7/socket.py", line 380, in read
    data = self._sock.recv(left)
timeout: timed out

2014-10-26 19:43:57,920 crawl.py[line:32] ERROR generic exception: Traceback (most recent call last):
  File "./crawl.py", line 19, in url_read
    content=urllib2.urlopen(req,timeout=60).read()
  File "/home/zhouqiang/.jumbo/lib/python2.7/socket.py", line 351, in read
    data = self._sock.recv(rbufsize)
  File "/home/zhouqiang/.jumbo/lib/python2.7/httplib.py", line 541, in read
    return self._read_chunked(amt)
  File "/home/zhouqiang/.jumbo/lib/python2.7/httplib.py", line 601, in _read_chunked
    value.append(self._safe_read(chunk_left))
  File "/home/zhouqiang/.jumbo/lib/python2.7/httplib.py", line 647, in _safe_read
    chunk = self.fp.read(min(amt, MAXAMOUNT))
  File "/home/zhouqiang/.jumbo/lib/python2.7/socket.py", line 380, in read
    data = self._sock.recv(left)
timeout: timed out

2014-10-26 23:24:08,165 crawl.py[line:51] ERROR generic exception: Traceback (most recent call last):
  File "../lib/crawl.py", line 41, in get_code
    content=urllib2.urlopen(req,timeout=60)
  File "/System/Library/Frameworks/Python.framework/Versions/2.7/lib/python2.7/urllib2.py", line 127, in urlopen
    return _opener.open(url, data, timeout)
  File "/System/Library/Frameworks/Python.framework/Versions/2.7/lib/python2.7/urllib2.py", line 404, in open
    response = self._open(req, data)
  File "/System/Library/Frameworks/Python.framework/Versions/2.7/lib/python2.7/urllib2.py", line 422, in _open
    '_open', req)
  File "/System/Library/Frameworks/Python.framework/Versions/2.7/lib/python2.7/urllib2.py", line 382, in _call_chain
    result = func(*args)
  File "/System/Library/Frameworks/Python.framework/Versions/2.7/lib/python2.7/urllib2.py", line 1214, in http_open
    return self.do_open(httplib.HTTPConnection, req)
  File "/System/Library/Frameworks/Python.framework/Versions/2.7/lib/python2.7/urllib2.py", line 1187, in do_open
    r = h.getresponse(buffering=True)
  File "/System/Library/Frameworks/Python.framework/Versions/2.7/lib/python2.7/httplib.py", line 1045, in getresponse
    response.begin()
  File "/System/Library/Frameworks/Python.framework/Versions/2.7/lib/python2.7/httplib.py", line 409, in begin
    version, status, reason = self._read_status()
  File "/System/Library/Frameworks/Python.framework/Versions/2.7/lib/python2.7/httplib.py", line 365, in _read_status
    line = self.fp.readline(_MAXLINE + 1)
  File "/System/Library/Frameworks/Python.framework/Versions/2.7/lib/python2.7/socket.py", line 476, in readline
    data = self._sock.recv(self._rbufsize)
timeout: timed out

2014-10-26 23:24:08,165 crawl.py[line:51] ERROR generic exception: Traceback (most recent call last):
  File "../lib/crawl.py", line 41, in get_code
    content=urllib2.urlopen(req,timeout=60)
  File "/System/Library/Frameworks/Python.framework/Versions/2.7/lib/python2.7/urllib2.py", line 127, in urlopen
    return _opener.open(url, data, timeout)
  File "/System/Library/Frameworks/Python.framework/Versions/2.7/lib/python2.7/urllib2.py", line 404, in open
    response = self._open(req, data)
  File "/System/Library/Frameworks/Python.framework/Versions/2.7/lib/python2.7/urllib2.py", line 422, in _open
    '_open', req)
  File "/System/Library/Frameworks/Python.framework/Versions/2.7/lib/python2.7/urllib2.py", line 382, in _call_chain
    result = func(*args)
  File "/System/Library/Frameworks/Python.framework/Versions/2.7/lib/python2.7/urllib2.py", line 1214, in http_open
    return self.do_open(httplib.HTTPConnection, req)
  File "/System/Library/Frameworks/Python.framework/Versions/2.7/lib/python2.7/urllib2.py", line 1187, in do_open
    r = h.getresponse(buffering=True)
  File "/System/Library/Frameworks/Python.framework/Versions/2.7/lib/python2.7/httplib.py", line 1045, in getresponse
    response.begin()
  File "/System/Library/Frameworks/Python.framework/Versions/2.7/lib/python2.7/httplib.py", line 409, in begin
    version, status, reason = self._read_status()
  File "/System/Library/Frameworks/Python.framework/Versions/2.7/lib/python2.7/httplib.py", line 365, in _read_status
    line = self.fp.readline(_MAXLINE + 1)
  File "/System/Library/Frameworks/Python.framework/Versions/2.7/lib/python2.7/socket.py", line 476, in readline
    data = self._sock.recv(self._rbufsize)
timeout: timed out

2014-10-26 23:26:32,904 crawl.py[line:51] ERROR generic exception: Traceback (most recent call last):
  File "../lib/crawl.py", line 41, in get_code
    content=urllib2.urlopen(req,timeout=60)
  File "/System/Library/Frameworks/Python.framework/Versions/2.7/lib/python2.7/urllib2.py", line 127, in urlopen
    return _opener.open(url, data, timeout)
  File "/System/Library/Frameworks/Python.framework/Versions/2.7/lib/python2.7/urllib2.py", line 404, in open
    response = self._open(req, data)
  File "/System/Library/Frameworks/Python.framework/Versions/2.7/lib/python2.7/urllib2.py", line 422, in _open
    '_open', req)
  File "/System/Library/Frameworks/Python.framework/Versions/2.7/lib/python2.7/urllib2.py", line 382, in _call_chain
    result = func(*args)
  File "/System/Library/Frameworks/Python.framework/Versions/2.7/lib/python2.7/urllib2.py", line 1214, in http_open
    return self.do_open(httplib.HTTPConnection, req)
  File "/System/Library/Frameworks/Python.framework/Versions/2.7/lib/python2.7/urllib2.py", line 1187, in do_open
    r = h.getresponse(buffering=True)
  File "/System/Library/Frameworks/Python.framework/Versions/2.7/lib/python2.7/httplib.py", line 1045, in getresponse
    response.begin()
  File "/System/Library/Frameworks/Python.framework/Versions/2.7/lib/python2.7/httplib.py", line 409, in begin
    version, status, reason = self._read_status()
  File "/System/Library/Frameworks/Python.framework/Versions/2.7/lib/python2.7/httplib.py", line 365, in _read_status
    line = self.fp.readline(_MAXLINE + 1)
  File "/System/Library/Frameworks/Python.framework/Versions/2.7/lib/python2.7/socket.py", line 476, in readline
    data = self._sock.recv(self._rbufsize)
timeout: timed out

2014-10-27 00:53:12,368 crawl.py[line:35] ERROR generic exception: Traceback (most recent call last):
  File "../lib/crawl.py", line 22, in url_read
    content=urllib2.urlopen(req,timeout=60).read()
  File "/home/zhouqiang/.jumbo/lib/python2.7/socket.py", line 351, in read
    data = self._sock.recv(rbufsize)
  File "/home/zhouqiang/.jumbo/lib/python2.7/httplib.py", line 541, in read
    return self._read_chunked(amt)
  File "/home/zhouqiang/.jumbo/lib/python2.7/httplib.py", line 601, in _read_chunked
    value.append(self._safe_read(chunk_left))
  File "/home/zhouqiang/.jumbo/lib/python2.7/httplib.py", line 647, in _safe_read
    chunk = self.fp.read(min(amt, MAXAMOUNT))
  File "/home/zhouqiang/.jumbo/lib/python2.7/socket.py", line 380, in read
    data = self._sock.recv(left)
timeout: timed out

2014-10-27 00:53:14,063 crawl.py[line:35] ERROR generic exception: Traceback (most recent call last):
  File "../lib/crawl.py", line 22, in url_read
    content=urllib2.urlopen(req,timeout=60).read()
  File "/home/zhouqiang/.jumbo/lib/python2.7/socket.py", line 351, in read
    data = self._sock.recv(rbufsize)
  File "/home/zhouqiang/.jumbo/lib/python2.7/httplib.py", line 541, in read
    return self._read_chunked(amt)
  File "/home/zhouqiang/.jumbo/lib/python2.7/httplib.py", line 601, in _read_chunked
    value.append(self._safe_read(chunk_left))
  File "/home/zhouqiang/.jumbo/lib/python2.7/httplib.py", line 647, in _safe_read
    chunk = self.fp.read(min(amt, MAXAMOUNT))
  File "/home/zhouqiang/.jumbo/lib/python2.7/socket.py", line 380, in read
    data = self._sock.recv(left)
timeout: timed out

2014-10-27 00:54:13,326 crawl.py[line:35] ERROR generic exception: Traceback (most recent call last):
  File "../lib/crawl.py", line 22, in url_read
    content=urllib2.urlopen(req,timeout=60).read()
  File "/home/zhouqiang/.jumbo/lib/python2.7/socket.py", line 351, in read
    data = self._sock.recv(rbufsize)
  File "/home/zhouqiang/.jumbo/lib/python2.7/httplib.py", line 541, in read
    return self._read_chunked(amt)
  File "/home/zhouqiang/.jumbo/lib/python2.7/httplib.py", line 601, in _read_chunked
    value.append(self._safe_read(chunk_left))
  File "/home/zhouqiang/.jumbo/lib/python2.7/httplib.py", line 647, in _safe_read
    chunk = self.fp.read(min(amt, MAXAMOUNT))
  File "/home/zhouqiang/.jumbo/lib/python2.7/socket.py", line 380, in read
    data = self._sock.recv(left)
timeout: timed out

2014-10-27 00:55:44,480 crawl.py[line:35] ERROR generic exception: Traceback (most recent call last):
  File "../lib/crawl.py", line 22, in url_read
    content=urllib2.urlopen(req,timeout=60).read()
  File "/home/zhouqiang/.jumbo/lib/python2.7/socket.py", line 351, in read
    data = self._sock.recv(rbufsize)
  File "/home/zhouqiang/.jumbo/lib/python2.7/httplib.py", line 541, in read
    return self._read_chunked(amt)
  File "/home/zhouqiang/.jumbo/lib/python2.7/httplib.py", line 592, in _read_chunked
    value.append(self._safe_read(amt))
  File "/home/zhouqiang/.jumbo/lib/python2.7/httplib.py", line 647, in _safe_read
    chunk = self.fp.read(min(amt, MAXAMOUNT))
  File "/home/zhouqiang/.jumbo/lib/python2.7/socket.py", line 380, in read
    data = self._sock.recv(left)
timeout: timed out

2014-11-24 13:20:21,641 dammit.py[line:369] WARNING Some characters could not be decoded, and were replaced with REPLACEMENT CHARACTER.
2014-11-24 13:21:51,488 dammit.py[line:369] WARNING Some characters could not be decoded, and were replaced with REPLACEMENT CHARACTER.
2014-11-25 00:21:18,483 crawl.py[line:39] ERROR generic exception: Traceback (most recent call last):
  File "../lib/crawl.py", line 27, in url_read
    return content
NameError: global name 'content' is not defined

2014-11-25 00:21:18,690 crawl.py[line:39] ERROR generic exception: Traceback (most recent call last):
  File "../lib/crawl.py", line 27, in url_read
    return content
NameError: global name 'content' is not defined

2014-11-25 00:21:18,901 crawl.py[line:39] ERROR generic exception: Traceback (most recent call last):
  File "../lib/crawl.py", line 27, in url_read
    return content
NameError: global name 'content' is not defined

2014-11-25 00:21:19,102 crawl.py[line:74] DEBUG Crawl Failed: http://www.sina.com.cn
2014-11-25 00:26:51,199 crawl.py[line:39] ERROR generic exception: Traceback (most recent call last):
  File "../lib/crawl.py", line 27, in url_read
    return content
NameError: global name 'content' is not defined

2014-11-25 00:26:51,449 crawl.py[line:39] ERROR generic exception: Traceback (most recent call last):
  File "../lib/crawl.py", line 27, in url_read
    return content
NameError: global name 'content' is not defined

2014-11-25 00:26:51,739 crawl.py[line:39] ERROR generic exception: Traceback (most recent call last):
  File "../lib/crawl.py", line 27, in url_read
    return content
NameError: global name 'content' is not defined

2014-11-25 00:26:51,939 crawl.py[line:74] DEBUG Crawl Failed: http://www.sina.com.cn
2014-11-25 00:29:06,454 crawl.py[line:39] ERROR generic exception: Traceback (most recent call last):
  File "../lib/crawl.py", line 27, in url_read
    return content
NameError: global name 'content' is not defined

2014-11-25 00:29:06,688 crawl.py[line:39] ERROR generic exception: Traceback (most recent call last):
  File "../lib/crawl.py", line 27, in url_read
    return content
NameError: global name 'content' is not defined

2014-11-25 00:29:06,901 crawl.py[line:39] ERROR generic exception: Traceback (most recent call last):
  File "../lib/crawl.py", line 27, in url_read
    return content
NameError: global name 'content' is not defined

2014-11-25 00:29:07,101 crawl.py[line:74] DEBUG Crawl Failed: http://www.sina.com.cn
2014-11-25 00:30:43,124 crawl.py[line:39] ERROR generic exception: Traceback (most recent call last):
  File "../lib/crawl.py", line 27, in url_read
    return content
NameError: global name 'content' is not defined

2014-11-25 00:30:43,359 crawl.py[line:39] ERROR generic exception: Traceback (most recent call last):
  File "../lib/crawl.py", line 27, in url_read
    return content
NameError: global name 'content' is not defined

2014-11-25 00:30:43,566 crawl.py[line:39] ERROR generic exception: Traceback (most recent call last):
  File "../lib/crawl.py", line 27, in url_read
    return content
NameError: global name 'content' is not defined

2014-11-25 00:30:43,766 crawl.py[line:74] DEBUG Crawl Failed: http://www.sina.com.cn
